data/sample-replay/iceberg_scenario_expected.csv
aggressor_id,passive_id,price,quantity
5,1,10050,100
6,1,10050,100
7,1,10050,100
10,3,10040,80
11,1,10050,100
12,8,10050,50
12,1,10050,50
14,1,10050,50
14,13,10050,50
14,2,10060,50
16,15,10055,80
16,15,10055,20
17,15,10055,60
17,15,10055,40
18,3,10040,70
18,9,10040,30
19,15,10055,40
19,15,10055,80
19,15,10055,80
