data/sample-replay/small_market_expected.csv
aggressor_id,passive_id,price,quantity
7,1,10050,60
8,1,10050,40
9,4,10040,70
10,4,10040,30
11,2,10060,180
12,5,10030,50
13,2,10060,20
13,3,10070,100
15,14,10045,80
18,17,10055,60
20,19,10060,40
21,3,10070,50
22,19,10060,60
22,17,10055,30
23,22,10040,10
24,23,10050,65
25,24,10050,10
26,25,10060,40
