data/sample-replay/stop_scenario_expected.csv
aggressor_id,passive_id,price,quantity
9,1,10050,50
5,1,10050,50
5,2,10060,30
10,7,10055,100
11,2,10060,80
12,3,10040,60
6,3,10040,60
8,3,10040,30
13,8,10035,30
15,8,10035,10
15,14,10050,30
17,16,10045,30
19,14,10050,20
19,18,10055,60
19,2,10060,20
21,20,10050,40
21,2,10060,10
23,22,10040,60
24,4,10030,100
