tests/replay/data/basic_limit_expected.csv
aggressor_id,passive_id,price,quantity
7,1,10050,60
8,1,10050,40
9,4,10040,70
10,4,10040,30
11,2,10060,50
12,5,10030,40
13,3,10070,80
14,5,10030,10
14,6,10020,50
16,15,10050,10
18,17,10060,30
18,15,10050,10
19,18,10050,10
20,19,10050,20
