tests/replay/data/stop_trigger_expected.csv
aggressor_id,passive_id,price,quantity
4,1,10050,50
100,1,10050,30
6,2,10040,80
101,2,10040,20
8,1,10050,20
8,7,10050,50
8,3,10060,30
